Workbook

Sheet Matriz de trazabilidad
A2: Matriz de trazabilidad
A4: Seleccione los códigos amarillos. Las descripciones y el estado de cobertura se completan automáticamente desde las hojas de apoyo.
A5: Resumen | B5: Relaciones registradas | C5: =COUNTIF(G8:G85,"?*") -> 78 | D5: Completas | E5: =COUNTIF(B8:B85,"Trazabilidad completa") -> 0 | F5: Con pendientes | G5: =COUNTIF(G8:G85,"?*")-COUNTIF(B8:B85,"Trazabilidad completa") -> 78 | H5: Pruebas aprobadas | I5: =COUNTIF(O8:O85,"Aprobado") -> 0 | J5: Pruebas fallidas | K5: =COUNTIF(O8:O85,"Fallido") -> 0
A7: N.º | B7: Estado de trazabilidad | C7: ID Objetivo | D7: Objetivo | E7: ID Proceso | F7: Proceso / Módulo | G7: ID Requerimiento | H7: Requerimiento | I7: ID HU | J7: Historia de usuario | K7: ID Criterio | L7: Criterio de aceptación | M7: ID Caso de prueba | N7: Caso / Escenario | O7: Estado prueba | P7: ID Evidencia | Q7: Evidencia / Enlace | R7: Observaciones
A8: 1 | B8: =IF($G8="","",IF($K8="","Falta criterio",IFERROR(IF(VLOOKUP($K8,'Historias y criterios'!$A$6:$P$83,3,FALSE)<>$G8,"Revisar relación requisito-criterio",IF($M8="","Falta caso de prueba",IF(VLOOKUP($M8,'Casos y evidencias'!$A$6:$O$83,2,FALSE)<>$K8,"Revisar relación criterio-caso",IF($O8="Aprobado",IF($P8="","Falta evidencia","Trazabilidad completa"),IF($O8="Fallido","Prueba fallida",IF($O8="Bloqueado","Prueba bloqueada","Prueba pendiente")))))),"ID no encontrado"))) -> Prueba pendiente | C8: =IF($G8="","",IFERROR(IF(VLOOKUP($G8,Requerimientos!$A$6:$M$43,2,FALSE)="","",VLOOKUP($G8,Requerimientos!$A$6:$M$43,2,FALSE)),"ID no encontrado")) -> OBJ-001 | D8: =IF($C8="","",IFERROR(IF(VLOOKUP($C8,'Objetivos y procesos'!$A$6:$H$35,2,FALSE)="","",VLOOKUP($C8,'Objetivos y procesos'!$A$6:$H$35,2,FALSE)),"ID no encontrado")) -> Proteger la plataforma y asegurar que cada usuario opere con el perfil, empresa y vendedor correctos. | E8: =IF($G8="","",IFERROR(IF(VLOOKUP($G8,Requerimientos!$A$6:$M$43,3,FALSE)="","",VLOOKUP($G8,Requerimientos!$A$6:$M$43,3,FALSE)),"ID no encontrado")) -> PR-01 | F8: =IF($E8="","",IFERROR(IF(INDEX('Objetivos y procesos'!$D$6:$D$35,MATCH($E8,'Objetivos y procesos'!$C$6:$C$35,0))="","",IF(INDEX('Objetivos y procesos'!$D$6:$D$35,MATCH($E8,'Objetivos y procesos'!$C$6:$C$35,0))=INDEX('Objetivos y procesos'!$E$6:$E$35,MATCH($E8,'Objetivos y procesos'!$C$6:$C$35,0)),INDEX('Objetivos y procesos'!$D$6:$D$35,MATCH($E8,'Objetivos y procesos'!$C$6:$C$35,0)),INDEX('Objetivos y procesos'!$D$6:$D$35,MATCH($E8,'Objetivos y procesos'!$C$6:$C$35,0))&IF(INDEX('Objetivos y procesos'!$E$6:$E$35,MATCH($E8,'Objetivos y procesos'!$C$6:$C$35,0))="",""," / "&INDEX('Objetivos y procesos'!$E$6:$E$35,MATCH($E8,'Objetivos y procesos'!$C$6:$C$35,0))))),"ID no encontrado")) -> Gestión de usuarios, roles y permisos | G8: RF-01 | H8: =IF($G8="","",IFERROR(IF(VLOOKUP($G8,Requerimientos!$A$6:$M$43,7,FALSE)="","",VLOOKUP($G8,Requerimientos!$A$6:$M$43,7,FALSE)),"ID no encontrado")) -> El sistema debe permitir que un usuario se autentique mediante usuario y contraseña. | I8: =IF($K8="","",IFERROR(IF(VLOOKUP($K8,'Historias y criterios'!$A$6:$P$83,2,FALSE)="","",VLOOKUP($K8,'Historias y criterios'!$A$6:$P$83,2,FALSE)),"ID no encontrado")) -> HU-001 | J8: =IF($K8="","",IFERROR(IF(VLOOKUP($K8,'Historias y criterios'!$A$6:$P$83,10,FALSE)="","",VLOOKUP($K8,'Historias y criterios'!$A$6:$P$83,10,FALSE)),"ID no encontrado")) -> Como usuario habilitado, quiero iniciar sesión de forma segura y mantener una sesión controlada, para acceder únicamente a las funciones autorizadas | K8: CA-001 | L8: =IF($K8="","",IFERROR(IF(VLOOKUP($K8,'Historias y criterios'!$A$6:$P$83,11,FALSE)="","",VLOOKUP($K8,'Historias y criterios'!$A$6:$P$83,11,FALSE)),"ID no encontrado")) -> Con credenciales válidas, el usuario activo ingresa a la plataforma. | M8: CP-001 | N8: =IF($M8="","",IFERROR(IF(VLOOKUP($M8,'Casos y evidencias'!$A$6:$O$83,5,FALSE)="","",VLOOKUP($M8,'Casos y evidencias'!$A$6:$O$83,5,FALSE)),"ID no encontrado")) -> Inicio de sesión con credenciales válidas | O8: =IF($M8="","",IFERROR(IF(VLOOKUP($M8,'Casos y evidencias'!$A$6:$O$83,10,FALSE)="","",VLOOKUP($M8,'Casos y evidencias'!$A$6:$O$83,10,FALSE)),"ID no encontrado")) -> No ejecutado | P8: =IF($M8="","",IFERROR(IF(VLOOKUP($M8,'Casos y evidencias'!$A$6:$O$83,11,FALSE)="","",VLOOKUP($M8,'Casos y evidencias'!$A$6:$O$83,11,FALSE)),"ID no encontrado")) | Q8: =IF($M8="","",IFERROR(IF(VLOOKUP($M8,'Casos y evidencias'!$A$6:$O$83,12,FALSE)="","",VLOOKUP($M8,'Casos y evidencias'!$A$6:$O$83,12,FALSE)),"ID no encontrado"))
A9: 2 | B9: =IF($G9="","",IF($K9="","Falta criterio",IFERROR(IF(VLOOKUP($K9,'Historias y criterios'!$A$6:$P$83,3,FALSE)<>$G9,"Revisar relación requisito-criterio",IF($M9="","Falta caso de prueba",IF(VLOOKUP($M9,'Casos y evidencias'!$A$6:$O$83,2,FALSE)<>$K9,"Revisar relación criterio-caso",IF($O9="Aprobado",IF($P9="","Falta evidencia","Trazabilidad completa"),IF($O9="Fallido","Prueba fallida",IF($O9="Bloqueado","Prueba bloqueada","Prueba pendiente")))))),"ID no encontrado"))) -> Prueba pendiente | C9: =IF($G9="","",IFERROR(IF(VLOOKUP($G9,Requerimientos!$A$6:$M$43,2,FALSE)="","",VLOOKUP($G9,Requerimientos!$A$6:$M$43,2,FALSE)),"ID no encontrado")) -> OBJ-001 | D9: =IF($C9="","",IFERROR(IF(VLOOKUP($C9,'Objetivos y procesos'!$A$6:$H$35,2,FALSE)="","",VLOOKUP($C9,'Objetivos y procesos'!$A$6:$H$35,2,FALSE)),"ID no encontrado")) -> Proteger la plataforma y asegurar que cada usuario opere con el perfil, empresa y vendedor correctos. | E9: =IF($G9="","",IFERROR(IF(VLOOKUP($G9,Requerimientos!$A$6:$M$43,3,FALSE)="","",VLOOKUP($G9,Requerimientos!$A$6:$M$43,3,FALSE)),"ID no encontrado")) -> PR-01 | F9: =IF($E9="","",IFERROR(IF(INDEX('Objetivos y procesos'!$D$6:$D$35,MATCH($E9,'Objetivos y procesos'!$C$6:$C$35,0))="","",IF(INDEX('Objetivos y procesos'!$D$6:$D$35,MATCH($E9,'Objetivos y procesos'!$C$6:$C$35,0))=INDEX('Objetivos y procesos'!$E$6:$E$35,MATCH($E9,'Objetivos y procesos'!$C$6:$C$35,0)),INDEX('Objetivos y procesos'!$D$6:$D$35,MATCH($E9,'Objetivos y procesos'!$C$6:$C$35,0)),INDEX('Objetivos y procesos'!$D$6:$D$35,MATCH($E9,'Objetivos y procesos'!$C$6:$C$35,0))&IF(INDEX('Objetivos y procesos'!$E$6:$E$35,MATCH($E9,'Objetivos y procesos'!$C$6:$C$35,0))="",""," / "&INDEX('Objetivos y procesos'!$E$6:$E$35,MATCH($E9,'Objetivos y procesos'!$C$6:$C$35,0))))),"ID no encontrado")) -> Gestión de usuarios, roles y permisos | G9: RF-01 | H9: =IF($G9="","",IFERROR(IF(VLOOKUP($G9,Requerimientos!$A$6:$M$43,7,FALSE)="","",VLOOKUP($G9,Requerimientos!$A$6:$M$43,7,FALSE)),"ID no encontrado")) -> El sistema debe permitir que un usuario se autentique mediante usuario y contraseña. | I9: =IF($K9="","",IFERROR(IF(VLOOKUP($K9,'Historias y criterios'!$A$6:$P$83,2,FALSE)="","",VLOOKUP($K9,'Historias y criterios'!$A$6:$P$83,2,FALSE)),"ID no encontrado")) -> HU-001 | J9: =IF($K9="","",IFERROR(IF(VLOOKUP($K9,'Historias y criterios'!$A$6:$P$83,10,FALSE)="","",VLOOKUP($K9,'Historias y criterios'!$A$6:$P$83,10,FALSE)),"ID no encontrado")) -> Como usuario habilitado, quiero iniciar sesión de forma segura y mantener una sesión controlada, para acceder únicamente a las funciones autorizadas | K9: CA-002 | L9: =IF($K9="","",IFERROR(IF(VLOOKUP($K9,'Historias y criterios'!$A$6:$P$83,11,FALSE)="","",VLOOKUP($K9,'Historias y criterios'!$A$6:$P$83,11,FALSE)),"ID no encontrado")) -> Las credenciales inválidas o de un usuario desactivado impiden el acceso y muestran un mensaje claro. | M9: CP-002 | N9: =IF($M9="","",IFERROR(IF(VLOOKUP($M9,'Casos y evidencias'!$A$6:$O$83,5,FALSE)="","",VLOOKUP($M9,'Casos y evidencias'!$A$6:$O$83,5,FALSE)),"ID no encontrado")) -> Acceso denegado con credenciales inválidas o usuario desactivado | O9: =IF($M9="","",IFERROR(IF(VLOOKUP($M9,'Casos y evidencias'!$A$6:$O$83,10,FALSE)="","",VLOOKUP($M9,'Casos y evidencias'!$A$6:$O$83,10,FALSE)),"ID no encontrado")) -> No ejecutado | P9: =IF($M9="","",IFERROR(IF(VLOOKUP($M9,'Casos y evidencias'!$A$6:$O$83,11,FALSE)="","",VLOOKUP($M9,'Casos y evidencias'!$A$6:$O$83,11,FALSE)),"ID no encontrado")) | Q9: =IF($M9="","",IFERROR(IF(VLOOKUP($M9,'Casos y evidencias'!$A$6:$O$83,12,FALSE)="","",VLOOKUP($M9,'Casos y evidencias'!$A$6:$O$83,12,FALSE)),"ID no encontrado"))
A10: 3 | B10: =IF($G10="","",IF($K10="","Falta criterio",IFERROR(IF(VLOOKUP($K10,'Historias y criterios'!$A$6:$P$83,3,FALSE)<>$G10,"Revisar relación requisito-criterio",IF($M10="","Falta caso de prueba",IF(VLOOKUP($M10,'Casos y evidencias'!$A$6:$O$83,2,FALSE)<>$K10,"Revisar relación criterio-caso",IF($O10="Aprobado",IF($P10="","Falta evidencia","Trazabilidad completa"),IF($O10="Fallido","Prueba fallida",IF($O10="Bloqueado","Prueba bloqueada","Prueba pendiente")))))),"ID no encontrado"))) -> Prueba pendiente | C10: =IF($G10="","",IFERROR(IF(VLOOKUP($G10,Requerimientos!$A$6:$M$43,2,FALSE)="","",VLOOKUP($G10,Requerimientos!$A$6:$M$43,2,FALSE)),"ID no encontrado")) -> OBJ-001 | D10: =IF($C10="","",IFERROR(IF(VLOOKUP($C10,'Objetivos y procesos'!$A$6:$H$35,2,FALSE)="","",VLOOKUP($C10,'Objetivos y procesos'!$A$6:$H$35,2,FALSE)),"ID no encontrado")) -> Proteger la plataforma y asegurar que cada usuario opere con el perfil, empresa y vendedor correctos. | E10: =IF($G10="","",IFERROR(IF(VLOOKUP($G10,Requerimientos!$A$6:$M$43,3,FALSE)="","",VLOOKUP($G10,Requerimientos!$A$6:$M$43,3,FALSE)),"ID no encontrado")) -> PR-01 | F10: =IF($E10="","",IFERROR(IF(INDEX('Objetivos y procesos'!$D$6:$D$35,MATCH($E10,'Objetivos y procesos'!$C$6:$C$35,0))="","",IF(INDEX('Objetivos y procesos'!$D$6:$D$35,MATCH($E10,'Objetivos y procesos'!$C$6:$C$35,0))=INDEX('Objetivos y procesos'!$E$6:$E$35,MATCH($E10,'Objetivos y procesos'!$C$6:$C$35,0)),INDEX('Objetivos y procesos'!$D$6:$D$35,MATCH($E10,'Objetivos y procesos'!$C$6:$C$35,0)),INDEX('Objetivos y procesos'!$D$6:$D$35,MATCH($E10,'Objetivos y procesos'!$C$6:$C$35,0))&IF(INDEX('Objetivos y procesos'!$E$6:$E$35,MATCH($E10,'Objetivos y procesos'!$C$6:$C$35,0))="",""," / "&INDEX('Objetivos y procesos'!$E$6:$E$35,MATCH($E10,'Objetivos y procesos'!$C$6:$C$35,0))))),"ID no encontrado")) -> Gestión de usuarios, roles y permisos | G10: RF-01 | H10: =IF($G10="","",IFERROR(IF(VLOOKUP($G10,Requerimientos!$A$6:$M$43,7,FALSE)="","",VLOOKUP($G10,Requerimientos!$A$6:$M$43,7,FALSE)),"ID no encontrado")) -> El sistema debe permitir que un usuario se autentique mediante usuario y contraseña. | I10: =IF($K10="","",IFERROR(IF(VLOOKUP($K10,'Historias y criterios'!$A$6:$P$83,2,FALSE)="","",VLOOKUP($K10,'Historias y criterios'!$A$6:$P$83,2,FALSE)),"ID no encontrado")) -> HU-001 | J10: =IF($K10="","",IFERROR(IF(VLOOKUP($K10,'Historias y criterios'!$A$6:$P$83,10,FALSE)="","",VLOOKUP($K10,'Historias y criterios'!$A$6:$P$83,10,FALSE)),"ID no encontrado")) -> Como usuario habilitado, quiero iniciar sesión de forma segura y mantener una sesión controlada, para acceder únicamente a las funciones autorizadas | K10: CA-003 | L10: =IF($K10="","",IFERROR(IF(VLOOKUP($K10,'Historias y criterios'!$A$6:$P$83,11,FALSE)="","",VLOOKUP($K10,'Historias y criterios'!$A$6:$P$83,11,FALSE)),"ID no encontrado")) -> La contraseña se almacena mediante hash, la sesión expira por inactividad y los intentos fallidos quedan auditados. | M10: CP-003 | N10: =IF($M10="","",IFERROR(IF(VLOOKUP($M10,'Casos y evidencias'!$A$6:$O$83,5,FALSE)="","",VLOOKUP($M10,'Casos y evidencias'!$A$6:$O$83,5,FALSE)),"ID no encontrado")) -> Hash de contraseña, expiración de sesión y auditoría | O10: =IF($M10="","",IFERROR(IF(VLOOKUP($M10,'Casos y evidencias'!$A$6:$O$83,10,FALSE)="","",VLOOKUP($M10,'Casos y evidencias'!$A$6:$O$83,10,FALSE)),"ID no encontrado")) -> No ejecutado | P10: =IF($M10="","",IFERROR(IF(VLOOKUP($M10,'Casos y evidencias'!$A$6:$O$83,11,FALSE)="","",VLOOKUP($M10,'Casos y evidencias'!$A$6:$O$83,11,FALSE)),"ID no encontrado")) | Q10: =IF($M10="","",IFERROR(IF(VLOOKUP($M10,'Casos y evidencias'!$A$6:$O$83,12,FALSE)="","",VLOOKUP($M10,'Casos y evidencias'!$A$6:$O$83,12,FALSE)),"ID no encontrado"))
A11: 4 | B11: =IF($G11="","",IF($K11="","Falta criterio",IFERROR(IF(VLOOKUP($K11,'Historias y criterios'!$A$6:$P$83,3,FALSE)<>$G11,"Revisar relación requisito-criterio",IF($M11="","Falta caso de prueba",IF(VLOOKUP($M11,'Casos y evidencias'!$A$6:$O$83,2,FALSE)<>$K11,"Revisar relación criterio-caso",IF($O11="Aprobado",IF($P11="","Falta evidencia","Trazabilidad completa"),IF($O11="Fallido","Prueba fallida",IF($O11="Bloqueado","Prueba bloqueada","Prueba pendiente")))))),"ID no encontrado"))) -> Prueba pendiente | C11: =IF($G11="","",IFERROR(IF(VLOOKUP($G11,Requerimientos!$A$6:$M$43,2,FALSE)="","",VLOOKUP($G11,Requerimientos!$A$6:$M$43,2,FALSE)),"ID no encontrado")) -> OBJ-001 | D11: =IF($C11="","",IFERROR(IF(VLOOKUP($C11,'Objetivos y procesos'!$A$6:$H$35,2,FALSE)="","",VLOOKUP($C11,'Objetivos y procesos'!$A$6:$H$35,2,FALSE)),"ID no encontrado")) -> Proteger la plataforma y asegurar que cada usuario opere con el perfil, empresa y vendedor correctos. | E11: =IF($G11="","",IFERROR(IF(VLOOKUP($G11,Requerimientos!$A$6:$M$43,3,FALSE)="","",VLOOKUP($G11,Requerimientos!$A$6:$M$43,3,FALSE)),"ID no encontrado")) -> PR-01 | F11: =IF($E11="","",IFERROR(IF(INDEX('Objetivos y procesos'!$D$6:$D$35,MATCH($E11,'Objetivos y procesos'!$C$6:$C$35,0))="","",IF(INDEX('Objetivos y procesos'!$D$6:$D$35,MATCH($E11,'Objetivos y procesos'!$C$6:$C$35,0))=INDEX('Objetivos y procesos'!$E$6:$E$35,MATCH($E11,'Objetivos y procesos'!$C$6:$C$35,0)),INDEX('Objetivos y procesos'!$D$6:$D$35,MATCH($E11,'Objetivos y procesos'!$C$6:$C$35,0)),INDEX('Objetivos y procesos'!$D$6:$D$35,MATCH($E11,'Objetivos y procesos'!$C$6:$C$35,0))&IF(INDEX('Objetivos y procesos'!$E$6:$E$35,MATCH($E11,'Objetivos y procesos'!$C$6:$C$35,0))="",""," / "&INDEX('Objetivos y procesos'!$E$6:$E$35,MATCH($E11,'Objetivos y procesos'!$C$6:$C$35,0))))),"ID no encontrado")) -> Gestión de usuarios, roles y permisos | G11: RF-02 | H11: =IF($G11="","",IFERROR(IF(VLOOKUP($G11,Requerimientos!$A$6:$M$43,7,FALSE)="","",VLOOKUP($G11,Requerimientos!$A$6:$M$43,7,FALSE)),"ID no encontrado")) -> El sistema debe permitir asignar a cada usuario un área, un cargo y un rol. | I11: =IF($K11="","",IFERROR(IF(VLOOKUP($K11,'Historias y criterios'!$A$6:$P$83,2,FALSE)="","",VLOOKUP($K11,'Historias y criterios'!$A$6:$P$83,2,FALSE)),"ID no encontrado")) -> HU-002 | J11: =IF($K11="","",IFERROR(IF(VLOOKUP($K11,'Historias y criterios'!$A$6:$P$83,10,FALSE)="","",VLOOKUP($K11,'Historias y criterios'!$A$6:$P$83,10,FALSE)),"ID no encontrado")) -> Como administrador, quiero crear, editar, desactivar y reactivar usuarios asignándoles área, cargo y rol, para mantener los accesos alineados con las responsabilidades de cada trabajador | K11: CA-004 | L11: =IF($K11="","",IFERROR(IF(VLOOKUP($K11,'Historias y criterios'!$A$6:$P$83,11,FALSE)="","",VLOOKUP($K11,'Historias y criterios'!$A$6:$P$83,11,FALSE)),"ID no encontrado")) -> El administrador crea y edita usuarios con área, cargo y rol obligatorios. | M11: CP-004 | N11: =IF($M11="","",IFERROR(IF(VLOOKUP($M11,'Casos y evidencias'!$A$6:$O$83,5,FALSE)="","",VLOOKUP($M11,'Casos y evidencias'!$A$6:$O$83,5,FALSE)),"ID no encontrado")) -> Creación y edición de usuario con área, cargo y rol | O11: =IF($M11="","",IFERROR(IF(VLOOKUP($M11,'Casos y evidencias'!$A$6:$O$83,10,FALSE)="","",VLOOKUP($M11,'Casos y evidencias'!$A$6:$O$83,10,FALSE)),"ID no encontrado")) -> No ejecutado | P11: =IF($M11="","",IFERROR(IF(VLOOKUP($M11,'Casos y evidencias'!$A$6:$O$83,11,FALSE)="","",VLOOKUP($M11,'Casos y evidencias'!$A$6:$O$83,11,FALSE)),"ID no encontrado")) | Q11: =IF($M11="","",IFERROR(IF(VLOOKUP($M11,'Casos y evidencias'!$A$6:$O$83,12,FALSE)="","",VLOOKUP($M11,'Casos y evidencias'!$A$6:$O$83,12,FALSE)),"ID no encontrado"))
A12: 5 | B12: =IF($G12="","",IF($K12="","Falta criterio",IFERROR(IF(VLOOKUP($K12,'Historias y criterios'!$A$6:$P$83,3,FALSE)<>$G12,"Revisar relación requisito-criterio",IF($M12="","Falta caso de prueba",IF(VLOOKUP($M12,'Casos y evidencias'!$A$6:$O$83,2,FALSE)<>$K12,"Revisar relación criterio-caso",IF($O12="Aprobado",IF($P12="","Falta evidencia","Trazabilidad completa"),IF($O12="Fallido","Prueba fallida",IF($O12="Bloqueado","Prueba bloqueada","Prueba pendiente")))))),"ID no encontrado"))) -> Prueba pendiente | C12: =IF($G12="","",IFERROR(IF(VLOOKUP($G12,Requerimientos!$A$6:$M$43,2,FALSE)="","",VLOOKUP($G12,Requerimientos!$A$6:$M$43,2,FALSE)),"ID no encontrado")) -> OBJ-001 | D12: =IF($C12="","",IFERROR(IF(VLOOKUP($C12,'Objetivos y procesos'!$A$6:$H$35,2,FALSE)="","",VLOOKUP($C12,'Objetivos y procesos'!$A$6:$H$35,2,FALSE)),"ID no encontrado")) -> Proteger la plataforma y asegurar que cada usuario opere con el perfil, empresa y vendedor correctos. | E12: =IF($G12="","",IFERROR(IF(VLOOKUP($G12,Requerimientos!$A$6:$M$43,3,FALSE)="","",VLOOKUP($G12,Requerimientos!$A$6:$M$43,3,FALSE)),"ID no encontrado")) -> PR-01 | F12: =IF($E12="","",IFERROR(IF(INDEX('Objetivos y procesos'!$D$6:$D$35,MATCH($E12,'Objetivos y procesos'!$C$6:$C$35,0))="","",IF(INDEX('Objetivos y procesos'!$D$6:$D$35,MATCH($E12,'Objetivos y procesos'!$C$6:$C$35,0))=INDEX('Objetivos y procesos'!$E$6:$E$35,MATCH($E12,'Objetivos y procesos'!$C$6:$C$35,0)),INDEX('Objetivos y procesos'!$D$6:$D$35,MATCH($E12,'Objetivos y procesos'!$C$6:$C$35,0)),INDEX('Objetivos y procesos'!$D$6:$D$35,MATCH($E12,'Objetivos y procesos'!$C$6:$C$35,0))&IF(INDEX('Objetivos y procesos'!$E$6:$E$35,MATCH($E12,'Objetivos y procesos'!$C$6:$C$35,0))="",""," / "&INDEX('Objetivos y procesos'!$E$6:$E$35,MATCH($E12,'Objetivos y procesos'!$C$6:$C$35,0))))),"ID no encontrado")) -> Gestión de usuarios, roles y permisos | G12: RF-04 | H12: =IF($G12="","",IFERROR(IF(VLOOKUP($G12,Requerimientos!$A$6:$M$43,7,FALSE)="","",VLOOKUP($G12,Requerimientos!$A$6:$M$43,7,FALSE)),"ID no encontrado")) -> El sistema debe permitir al administrador crear, editar, desactivar y reactivar usuarios. | I12: =IF($K12="","",IFERROR(IF(VLOOKUP($K12,'Historias y criterios'!$A$6:$P$83,2,FALSE)="","",VLOOKUP($K12,'Historias y criterios'!$A$6:$P$83,2,FALSE)),"ID no encontrado")) -> HU-002 | J12: =IF($K12="","",IFERROR(IF(VLOOKUP($K12,'Historias y criterios'!$A$6:$P$83,10,FALSE)="","",VLOOKUP($K12,'Historias y criterios'!$A$6:$P$83,10,FALSE)),"ID no encontrado")) -> Como administrador, quiero crear, editar, desactivar y reactivar usuarios asignándoles área, cargo y rol, para mantener los accesos alineados con las responsabilidades de cada trabajador | K12: CA-005 | L12: =IF($K12="","",IFERROR(IF(VLOOKUP($K12,'Historias y criterios'!$A$6:$P$83,11,FALSE)="","",VLOOKUP($K12,'Historias y criterios'!$A$6:$P$83,11,FALSE)),"ID no encontrado")) -> Un usuario se desactiva o reactiva sin eliminar su historial. | M12: CP-005 | N12: =IF($M12="","",IFERROR(IF(VLOOKUP($M12,'Casos y evidencias'!$A$6:$O$83,5,FALSE)="","",VLOOKUP($M12,'Casos y evidencias'!$A$6:$O$83,5,FALSE)),"ID no encontrado")) -> Desactivación y reactivación sin pérdida de historial | O12: =IF($M12="","",IFERROR(IF(VLOOKUP($M12,'Casos y evidencias'!$A$6:$O$83,10,FALSE)="","",VLOOKUP($M12,'Casos y evidencias'!$A$6:$O$83,10,FALSE)),"ID no encontrado")) -> No ejecutado | P12: =IF($M12="","",IFERROR(IF(VLOOKUP($M12,'Casos y evidencias'!$A$6:$O$83,11,FALSE)="","",VLOOKUP($M12,'Casos y evidencias'!$A$6:$O$83,11,FALSE)),"ID no encontrado")) | Q12: =IF($M12="","",IFERROR(IF(VLOOKUP($M12,'Casos y evidencias'!$A$6:$O$83,12,FALSE)="","",VLOOKUP($M12,'Casos y evidencias'!$A$6:$O$83,12,FALSE)),"ID no encontrado"))
A13: 6 | B13: =IF($G13="","",IF($K13="","Falta criterio",IFERROR(IF(VLOOKUP($K13,'Historias y criterios'!$A$6:$P$83,3,FALSE)<>$G13,"Revisar relación requisito-criterio",IF($M13="","Falta caso de prueba",IF(VLOOKUP($M13,'Casos y evidencias'!$A$6:$O$83,2,FALSE)<>$K13,"Revisar relación criterio-caso",IF($O13="Aprobado",IF($P13="","Falta evidencia","Trazabilidad completa"),IF($O13="Fallido","Prueba fallida",IF($O13="Bloqueado","Prueba bloqueada","Prueba pendiente")))))),"ID no encontrado"))) -> Prueba pendiente | C13: =IF($G13="","",IFERROR(IF(VLOOKUP($G13,Requerimientos!$A$6:$M$43,2,FALSE)="","",VLOOKUP($G13,Requerimientos!$A$6:$M$43,2,FALSE)),"ID no encontrado")) -> OBJ-001 | D13: =IF($C13="","",IFERROR(IF(VLOOKUP($C13,'Objetivos y procesos'!$A$6:$H$35,2,FALSE)="","",VLOOKUP($C13,'Objetivos y procesos'!$A$6:$H$35,2,FALSE)),"ID no encontrado")) -> Proteger la plataforma y asegurar que cada usuario opere con el perfil, empresa y vendedor correctos. | E13: =IF($G13="","",IFERROR(IF(VLOOKUP($G13,Requerimientos!$A$6:$M$43,3,FALSE)="","",VLOOKUP($G13,Requerimientos!$A$6:$M$43,3,FALSE)),"ID no encontrado")) -> PR-01 | F13: =IF($E13="","",IFERROR(IF(INDEX('Objetivos y procesos'!$D$6:$D$35,MATCH($E13,'Objetivos y procesos'!$C$6:$C$35,0))="","",IF(INDEX('Objetivos y procesos'!$D$6:$D$35,MATCH($E13,'Objetivos y procesos'!$C$6:$C$35,0))=INDEX('Objetivos y procesos'!$E$6:$E$35,MATCH($E13,'Objetivos y procesos'!$C$6:$C$35,0)),INDEX('Objetivos y procesos'!$D$6:$D$35,MATCH($E13,'Objetivos y procesos'!$C$6:$C$35,0)),INDEX('Objetivos y procesos'!$D$6:$D$35,MATCH($E13,'Objetivos y procesos'!$C$6:$C$35,0))&IF(INDEX('Objetivos y procesos'!$E$6:$E$35,MATCH($E13,'Objetivos y procesos'!$C$6:$C$35,0))="",""," / "&INDEX('Objetivos y procesos'!$E$6:$E$35,MATCH($E13,'Objetivos y procesos'!$C$6:$C$35,0))))),"ID no encontrado")) -> Gestión de usuarios, roles y permisos | G13: RF-04 | H13: =IF($G13="","",IFERROR(IF(VLOOKUP($G13,Requerimientos!$A$6:$M$43,7,FALSE)="","",VLOOKUP($G13,Requerimientos!$A$6:$M$43,7,FALSE)),"ID no encontrado")) -> El sistema debe permitir al administrador crear, editar, desactivar y reactivar usuarios. | I13: =IF($K13="","",IFERROR(IF(VLOOKUP($K13,'Historias y criterios'!$A$6:$P$83,2,FALSE)="","",VLOOKUP($K13,'Historias y criterios'!$A$6:$P$83,2,FALSE)),"ID no encontrado")) -> HU-002 | J13: =IF($K13="","",IFERROR(IF(VLOOKUP($K13,'Historias y criterios'!$A$6:$P$83,10,FALSE)="","",VLOOKUP($K13,'Historias y criterios'!$A$6:$P$83,10,FALSE)),"ID no encontrado")) -> Como administrador, quiero crear, editar, desactivar y reactivar usuarios asignándoles área, cargo y rol, para mantener los accesos alineados con las responsabilidades de cada trabajador | K13: CA-006 | L13: =IF($K13="","",IFERROR(IF(VLOOKUP($K13,'Historias y criterios'!$A$6:$P$83,11,FALSE)="","",VLOOKUP($K13,'Historias y criterios'!$A$6:$P$83,11,FALSE)),"ID no encontrado")) -> Solo el administrador puede ejecutar estas operaciones y un usuario desactivado no puede iniciar sesión. | M13: CP-006 | N13: =IF($M13="","",IFERROR(IF(VLOOKUP($M13,'Casos y evidencias'!$A$6:$O$83,5,FALSE)="","",VLOOKUP($M13,'Casos y evidencias'!$A$6:$O$83,5,FALSE)),"ID no encontrado")) -> Operaciones exclusivas del administrador | O13: =IF($M13="","",IFERROR(IF(VLOOKUP($M13,'Casos y evidencias'!$A$6:$O$83,10,FALSE)="","",VLOOKUP($M13,'Casos y evidencias'!$A$6:$O$83,10,FALSE)),"ID no encontrado")) -> No ejecutado | P13: =IF($M13="","",IFERROR(IF(VLOOKUP($M13,'Casos y evidencias'!$A$6:$O$83,11,FALSE)="","",VLOOKUP($M13,'Casos y evidencias'!$A$6:$O$83,11,FALSE)),"ID no encontrado")) | Q13: =IF($M13="","",IFERROR(IF(VLOOKUP($M13,'Casos y evidencias'!$A$6:$O$83,12,FALSE)="","",VLOOKUP($M13,'Casos y evidencias'!$A$6:$O$83,12,FALSE)),"ID no encontrado"))
A14: 7 | B14: =IF($G14="","",IF($K14="","Falta criterio",IFERROR(IF(VLOOKUP($K14,'Historias y criterios'!$A$6:$P$83,3,FALSE)<>$G14,"Revisar relación requisito-criterio",IF($M14="","Falta caso de prueba",IF(VLOOKUP($M14,'Casos y evidencias'!$A$6:$O$83,2,FALSE)<>$K14,"Revisar relación criterio-caso",IF($O14="Aprobado",IF($P14="","Falta evidencia","Trazabilidad completa"),IF($O14="Fallido","Prueba fallida",IF($O14="Bloqueado","Prueba bloqueada","Prueba pendiente")))))),"ID no encontrado"))) -> Prueba pendiente | C14: =IF($G14="","",IFERROR(IF(VLOOKUP($G14,Requerimientos!$A$6:$M$43,2,FALSE)="","",VLOOKUP($G14,Requerimientos!$A$6:$M$43,2,FALSE)),"ID no encontrado")) -> OBJ-001 | D14: =IF($C14="","",IFERROR(IF(VLOOKUP($C14,'Objetivos y procesos'!$A$6:$H$35,2,FALSE)="","",VLOOKUP($C14,'Objetivos y procesos'!$A$6:$H$35,2,FALSE)),"ID no encontrado")) -> Proteger la plataforma y asegurar que cada usuario opere con el perfil, empresa y vendedor correctos. | E14: =IF($G14="","",IFERROR(IF(VLOOKUP($G14,Requerimientos!$A$6:$M$43,3,FALSE)="","",VLOOKUP($G14,Requerimientos!$A$6:$M$43,3,FALSE)),"ID no encontrado")) -> PR-01 | F14: =IF($E14="","",IFERROR(IF(INDEX('Objetivos y procesos'!$D$6:$D$35,MATCH($E14,'Objetivos y procesos'!$C$6:$C$35,0))="","",IF(INDEX('Objetivos y procesos'!$D$6:$D$35,MATCH($E14,'Objetivos y procesos'!$C$6:$C$35,0))=INDEX('Objetivos y procesos'!$E$6:$E$35,MATCH($E14,'Objetivos y procesos'!$C$6:$C$35,0)),INDEX('Objetivos y procesos'!$D$6:$D$35,MATCH($E14,'Objetivos y procesos'!$C$6:$C$35,0)),INDEX('Objetivos y procesos'!$D$6:$D$35,MATCH($E14,'Objetivos y procesos'!$C$6:$C$35,0))&IF(INDEX('Objetivos y procesos'!$E$6:$E$35,MATCH($E14,'Objetivos y procesos'!$C$6:$C$35,0))="",""," / "&INDEX('Objetivos y procesos'!$E$6:$E$35,MATCH($E14,'Objetivos y procesos'!$C$6:$C$35,0))))),"ID no encontrado")) -> Gestión de usuarios, roles y permisos | G14: RF-03 | H14: =IF($G14="","",IFERROR(IF(VLOOKUP($G14,Requerimientos!$A$6:$M$43,7,FALSE)="","",VLOOKUP($G14,Requerimientos!$A$6:$M$43,7,FALSE)),"ID no encontrado")) -> El sistema debe restringir las funciones y los datos visibles según el rol, el área y el cargo del usuario. | I14: =IF($K14="","",IFERROR(IF(VLOOKUP($K14,'Historias y criterios'!$A$6:$P$83,2,FALSE)="","",VLOOKUP($K14,'Historias y criterios'!$A$6:$P$83,2,FALSE)),"ID no encontrado")) -> HU-003 | J14: =IF($K14="","",IFERROR(IF(VLOOKUP($K14,'Historias y criterios'!$A$6:$P$83,10,FALSE)="","",VLOOKUP($K14,'Historias y criterios'!$A$6:$P$83,10,FALSE)),"ID no encontrado")) -> Como administrador, quiero definir permisos por rol, área y cargo, además de grupos autorizadores por tipo de solicitud, para controlar qué funciones, datos y decisiones corresponden a cada usuario | K14: CA-007 | L14: =IF($K14="","",IFERROR(IF(VLOOKUP($K14,'Historias y criterios'!$A$6:$P$83,11,FALSE)="","",VLOOKUP($K14,'Historias y criterios'!$A$6:$P$83,11,FALSE)),"ID no encontrado")) -> Los permisos efectivos suman los permisos directos, del área y del cargo. | M14: CP-007 | N14: =IF($M14="","",IFERROR(IF(VLOOKUP($M14,'Casos y evidencias'!$A$6:$O$83,5,FALSE)="","",VLOOKUP($M14,'Casos y evidencias'!$A$6:$O$83,5,FALSE)),"ID no encontrado")) -> Cálculo de permisos efectivos | O14: =IF($M14="","",IFERROR(IF(VLOOKUP($M14,'Casos y evidencias'!$A$6:$O$83,10,FALSE)="","",VLOOKUP($M14,'Casos y evidencias'!$A$6:$O$83,10,FALSE)),"ID no encontrado")) -> No ejecutado | P14: =IF($M14="","",IFERROR(IF(VLOOKUP($M14,'Casos y evidencias'!$A$6:$O$83,11,FALSE)="","",VLOOKUP($M14,'Casos y evidencias'!$A$6:$O$83,11,FALSE)),"ID no encontrado")) | Q14: =IF($M14="","",IFERROR(IF(VLOOKUP($M14,'Casos y evidencias'!$A$6:$O$83,12,FALSE)="","",VLOOKUP($M14,'Casos y evidencias'!$A$6:$O$83,12,FALSE)),"ID no encontrado"))
A15: 8 | B15: =IF($G15="","",IF($K15="","Falta criterio",IFERROR(IF(VLOOKUP($K15,'Historias y criterios'!$A$6:$P$83,3,FALSE)<>$G15,"Revisar relación requisito-criterio",IF($M15="","Falta caso de prueba",IF(VLOOKUP($M15,'Casos y evidencias'!$A$6:$O$83,2,FALSE)<>$K15,"Revisar relación criterio-caso",IF($O15="Aprobado",IF($P15="","Falta evidencia","Trazabilidad completa"),IF($O15="Fallido","Prueba fallida",IF($O15="Bloqueado","Prueba bloqueada","Prueba pendiente")))))),"ID no encontrado"))) -> Prueba pendiente | C15: =IF($G15="","",IFERROR(IF(VLOOKUP($G15,Requerimientos!$A$6:$M$43,2,FALSE)="","",VLOOKUP($G15,Requerimientos!$A$6:$M$43,2,FALSE)),"ID no encontrado")) -> OBJ-001 | D15: =IF($C15="","",IFERROR(IF(VLOOKUP($C15,'Objetivos y procesos'!$A$6:$H$35,2,FALSE)="","",VLOOKUP($C15,'Objetivos y procesos'!$A$6:$H$35,2,FALSE)),"ID no encontrado")) -> Proteger la plataforma y asegurar que cada usuario opere con el perfil, empresa y vendedor correctos. | E15: =IF($G15="","",IFERROR(IF(VLOOKUP($G15,Requerimientos!$A$6:$M$43,3,FALSE)="","",VLOOKUP($G15,Requerimientos!$A$6:$M$43,3,FALSE)),"ID no encontrado")) -> PR-01 | F15: =IF($E15="","",IFERROR(IF(INDEX('Objetivos y procesos'!$D$6:$D$35,MATCH($E15,'Objetivos y procesos'!$C$6:$C$35,0))="","",IF(INDEX('Objetivos y procesos'!$D$6:$D$35,MATCH($E15,'Objetivos y procesos'!$C$6:$C$35,0))=INDEX('Objetivos y procesos'!$E$6:$E$35,MATCH($E15,'Objetivos y procesos'!$C$6:$C$35,0)),INDEX('Objetivos y procesos'!$D$6:$D$35,MATCH($E15,'Objetivos y procesos'!$C$6:$C$35,0)),INDEX('Objetivos y procesos'!$D$6:$D$35,MATCH($E15,'Objetivos y procesos'!$C$6:$C$35,0))&IF(INDEX('Objetivos y procesos'!$E$6:$E$35,MATCH($E15,'Objetivos y procesos'!$C$6:$C$35,0))="",""," / "&INDEX('Objetivos y procesos'!$E$6:$E$35,MATCH($E15,'Objetivos y procesos'!$C$6:$C$35,0))))),"ID no encontrado")) -> Gestión de usuarios, roles y permisos | G15: RF-03 | H15: =IF($G15="","",IFERROR(IF(VLOOKUP($G15,Requerimientos!$A$6:$M$43,7,FALSE)="","",VLOOKUP($G15,Requerimientos!$A$6:$M$43,7,FALSE)),"ID no encontrado")) -> El sistema debe restringir las funciones y los datos visibles según el rol, el área y el cargo del usuario. | I15: =IF($K15="","",IFERROR(IF(VLOOKUP($K15,'Historias y criterios'!$A$6:$P$83,2,FALSE)="","",VLOOKUP($K15,'Historias y criterios'!$A$6:$P$83,2,FALSE)),"ID no encontrado")) -> HU-003 | J15: =IF($K15="","",IFERROR(IF(VLOOKUP($K15,'Historias y criterios'!$A$6:$P$83,10,FALSE)="","",VLOOKUP($K15,'Historias y criterios'!$A$6:$P$83,10,FALSE)),"ID no encontrado")) -> Como administrador, quiero definir permisos por rol, área y cargo, además de grupos autorizadores por tipo de solicitud, para controlar qué funciones, datos y decisiones corresponden a cada usuario | K15: CA-008 | L15: =IF($K15="","",IFERROR(IF(VLOOKUP($K15,'Historias y criterios'!$A$6:$P$83,11,FALSE)="","",VLOOKUP($K15,'Historias y criterios'!$A$6:$P$83,11,FALSE)),"ID no encontrado")) -> Cada operación valida los permisos en el servidor. | M15: CP-008 | N15: =IF($M15="","",IFERROR(IF(VLOOKUP($M15,'Casos y evidencias'!$A$6:$O$83,5,FALSE)="","",VLOOKUP($M15,'Casos y evidencias'!$A$6:$O$83,5,FALSE)),"ID no encontrado")) -> Validación de permisos en el servidor | O15: =IF($M15="","",IFERROR(IF(VLOOKUP($M15,'Casos y evidencias'!$A$6:$O$83,10,FALSE)="","",VLOOKUP($M15,'Casos y evidencias'!$A$6:$O$83,10,FALSE)),"ID no encontrado")) -> No ejecutado | P15: =IF($M15="","",IFERROR(IF(VLOOKUP($M15,'Casos y evidencias'!$A$6:$O$83,11,FALSE)="","",VLOOKUP($M15,'Casos y evidencias'!$A$6:$O$83,11,FALSE)),"ID no encontrado")) | Q15: =IF($M15="","",IFERROR(IF(VLOOKUP($M15,'Casos y evidencias'!$A$6:$O$83,12,FALSE)="","",VLOOKUP($M15,'Casos y evidencias'!$A$6:$O$83,12,FALSE)),"ID no encontrado"))
A16: 9 | B16: =IF($G16="","",IF($K16="","Falta criterio",IFERROR(IF(VLOOKUP($K16,'Historias y criterios'!$A$6:$P$83,3,FALSE)<>$G16,"Revisar relación requisito-criterio",IF($M16="","Falta caso de prueba",IF(VLOOKUP($M16,'Casos y evidencias'!$A$6:$O$83,2,FALSE)<>$K16,"Revisar relación criterio-caso",IF($O16="Aprobado",IF($P16="","Falta evidencia","Trazabilidad completa"),IF($O16="Fallido","Prueba fallida",IF($O16="Bloqueado","Prueba bloqueada","Prueba pendiente")))))),"ID no encontrado"))) -> Prueba pendiente | C16: =IF($G16="","",IFERROR(IF(VLOOKUP($G16,Requerimientos!$A$6:$M$43,2,FALSE)="","",VLOOKUP($G16,Requerimientos!$A$6:$M$43,2,FALSE)),"ID no encontrado")) -> OBJ-001 | D16: =IF($C16="","",IFERROR(IF(VLOOKUP($C16,'Objetivos y procesos'!$A$6:$H$35,2,FALSE)="","",VLOOKUP($C16,'Objetivos y procesos'!$A$6:$H$35,2,FALSE)),"ID no encontrado")) -> Proteger la plataforma y asegurar que cada usuario opere con el perfil, empresa y vendedor correctos. | E16: =IF($G16="","",IFERROR(IF(VLOOKUP($G16,Requerimientos!$A$6:$M$43,3,FALSE)="","",VLOOKUP($G16,Requerimientos!$A$6:$M$43,3,FALSE)),"ID no encontrado")) -> PR-01 | F16: =IF($E16="","",IFERROR(IF(INDEX('Objetivos y procesos'!$D$6:$D$35,MATCH($E16,'Objetivos y procesos'!$C$6:$C$35,0))="","",IF(INDEX('Objetivos y procesos'!$D$6:$D$35,MATCH($E16,'Objetivos y procesos'!$C$6:$C$35,0))=INDEX('Objetivos y procesos'!$E$6:$E$35,MATCH($E16,'Objetivos y procesos'!$C$6:$C$35,0)),INDEX('Objetivos y procesos'!$D$6:$D$35,MATCH($E16,'Objetivos y procesos'!$C$6:$C$35,0)),INDEX('Objetivos y procesos'!$D$6:$D$35,MATCH($E16,'Objetivos y procesos'!$C$6:$C$35,0))&IF(INDEX('Objetivos y procesos'!$E$6:$E$35,MATCH($E16,'Objetivos y procesos'!$C$6:$C$35,0))="",""," / "&INDEX('Objetivos y procesos'!$E$6:$E$35,MATCH($E16,'Objetivos y procesos'!$C$6:$C$35,0))))),"ID no encontrado")) -> Gestión de usuarios, roles y permisos | G16: RF-29 | H16: =IF($G16="","",IFERROR(IF(VLOOKUP($G16,Requerimientos!$A$6:$M$43,7,FALSE)="","",VLOOKUP($G16,Requerimientos!$A$6:$M$43,7,FALSE)),"ID no encontrado")) -> El sistema debe permitir definir grupos de autorizadores por tipo de solicitud. | I16: =IF($K16="","",IFERROR(IF(VLOOKUP($K16,'Historias y criterios'!$A$6:$P$83,2,FALSE)="","",VLOOKUP($K16,'Historias y criterios'!$A$6:$P$83,2,FALSE)),"ID no encontrado")) -> HU-003 | J16: =IF($K16="","",IFERROR(IF(VLOOKUP($K16,'Historias y criterios'!$A$6:$P$83,10,FALSE)="","",VLOOKUP($K16,'Historias y criterios'!$A$6:$P$83,10,FALSE)),"ID no encontrado")) -> Como administrador, quiero definir permisos por rol, área y cargo, además de grupos autorizadores por tipo de solicitud, para controlar qué funciones, datos y decisiones corresponden a cada usuario | K16: CA-009 | L16: =IF($K16="","",IFERROR(IF(VLOOKUP($K16,'Historias y criterios'!$A$6:$P$83,11,FALSE)="","",VLOOKUP($K16,'Historias y criterios'!$A$6:$P$83,11,FALSE)),"ID no encontrado")) -> Es posible crear y modificar grupos por tipo de solicitud, siempre con al menos un integrante activo. | M16: CP-009 | N16: =IF($M16="","",IFERROR(IF(VLOOKUP($M16,'Casos y evidencias'!$A$6:$O$83,5,FALSE)="","",VLOOKUP($M16,'Casos y evidencias'!$A$6:$O$83,5,FALSE)),"ID no encontrado")) -> Gestión de grupos autorizadores por tipo de solicitud | O16: =IF($M16="","",IFERROR(IF(VLOOKUP($M16,'Casos y evidencias'!$A$6:$O$83,10,FALSE)="","",VLOOKUP($M16,'Casos y evidencias'!$A$6:$O$83,10,FALSE)),"ID no encontrado")) -> No ejecutado | P16: =IF($M16="","",IFERROR(IF(VLOOKUP($M16,'Casos y evidencias'!$A$6:$O$83,11,FALSE)="","",VLOOKUP($M16,'Casos y evidencias'!$A$6:$O$83,11,FALSE)),"ID no encontrado")) | Q16: =IF($M16="","",IFERROR(IF(VLOOKUP($M16,'Casos y evidencias'!$A$6:$O$83,12,FALSE)="","",VLOOKUP($M16,'Casos y evidencias'!$A$6:$O$83,12,FALSE)),"ID no encontrado"))
A17: 10 | B17: =IF($G17="","",IF($K17="","Falta criterio",IFERROR(IF(VLOOKUP($K17,'Historias y criterios'!$A$6:$P$83,3,FALSE)<>$G17,"Revisar relación requisito-criterio",IF($M17="","Falta caso de prueba",IF(VLOOKUP($M17,'Casos y evidencias'!$A$6:$O$83,2,FALSE)<>$K17,"Revisar relación criterio-caso",IF($O17="Aprobado",IF($P17="","Falta evidencia","Trazabilidad completa"),IF($O17="Fallido","Prueba fallida",IF($O17="Bloqueado","Prueba bloqueada","Prueba pendiente")))))),"ID no encontrado"))) -> Prueba pendiente | C17: =IF($G17="","",IFERROR(IF(VLOOKUP($G17,Requerimientos!$A$6:$M$43,2,FALSE)="","",VLOOKUP($G17,Requerimientos!$A$6:$M$43,2,FALSE)),"ID no encontrado")) -> OBJ-001 | D17: =IF($C17="","",IFERROR(IF(VLOOKUP($C17,'Objetivos y procesos'!$A$6:$H$35,2,FALSE)="","",VLOOKUP($C17,'Objetivos y procesos'!$A$6:$H$35,2,FALSE)),"ID no encontrado")) -> Proteger la plataforma y asegurar que cada usuario opere con el perfil, empresa y vendedor correctos. | E17: =IF($G17="","",IFERROR(IF(VLOOKUP($G17,Requerimientos!$A$6:$M$43,3,FALSE)="","",VLOOKUP($G17,Requerimientos!$A$6:$M$43,3,FALSE)),"ID no encontrado")) -> PR-01 | F17: =IF($E17="","",IFERROR(IF(INDEX('Objetivos y procesos'!$D$6:$D$35,MATCH($E17,'Objetivos y procesos'!$C$6:$C$35,0))="","",IF(INDEX('Objetivos y procesos'!$D$6:$D$35,MATCH($E17,'Objetivos y procesos'!$C$6:$C$35,0))=INDEX('Objetivos y procesos'!$E$6:$E$35,MATCH($E17,'Objetivos y procesos'!$C$6:$C$35,0)),INDEX('Objetivos y procesos'!$D$6:$D$35,MATCH($E17,'Objetivos y procesos'!$C$6:$C$35,0)),INDEX('Objetivos y procesos'!$D$6:$D$35,MATCH($E17,'Objetivos y procesos'!$C$6:$C$35,0))&IF(INDEX('Objetivos y procesos'!$E$6:$E$35,MATCH($E17,'Objetivos y procesos'!$C$6:$C$35,0))="",""," / "&INDEX('Objetivos y procesos'!$E$6:$E$35,MATCH($E17,'Objetivos y procesos'!$C$6:$C$35,0))))),"ID no encontrado")) -> Gestión de usuarios, roles y permisos | G17: RF-05 | H17: =IF($G17="","",IFERROR(IF(VLOOKUP($G17,Requerimientos!$A$6:$M$43,7,FALSE)="","",VLOOKUP($G17,Requerimientos!$A$6:$M$43,7,FALSE)),"ID no encontrado")) -> El sistema debe permitir al administrador definir y modificar los permisos asociados a cada rol, área y cargo. | I17: =IF($K17="","",IFERROR(IF(VLOOKUP($K17,'Historias y criterios'!$A$6:$P$83,2,FALSE)="","",VLOOKUP($K17,'Historias y criterios'!$A$6:$P$83,2,FALSE)),"ID no encontrado")) -> HU-003 | J17: =IF($K17="","",IFERROR(IF(VLOOKUP($K17,'Historias y criterios'!$A$6:$P$83,10,FALSE)="","",VLOOKUP($K17,'Historias y criterios'!$A$6:$P$83,10,FALSE)),"ID no encontrado")) -> Como administrador, quiero definir permisos por rol, área y cargo, además de grupos autorizadores por tipo de solicitud, para controlar qué funciones, datos y decisiones corresponden a cada usuario | K17: CA-010 | L17: =IF($K17="","",IFERROR(IF(VLOOKUP($K17,'Historias y criterios'!$A$6:$P$83,11,FALSE)="","",VLOOKUP($K17,'Historias y criterios'!$A$6:$P$83,11,FALSE)),"ID no encontrado")) -> Solo el administrador gestiona permisos y grupos. | M17: CP-010 | N17: =IF($M17="","",IFERROR(IF(VLOOKUP($M17,'Casos y evidencias'!$A$6:$O$83,5,FALSE)="","",VLOOKUP($M17,'Casos y evidencias'!$A$6:$O$83,5,FALSE)),"ID no encontrado")) -> Gestión de permisos exclusiva del administrador | O17: =IF($M17="","",IFERROR(IF(VLOOKUP($M17,'Casos y evidencias'!$A$6:$O$83,10,FALSE)="","",VLOOKUP($M17,'Casos y evidencias'!$A$6:$O$83,10,FALSE)),"ID no encontrado")) -> No ejecutado | P17: =IF($M17="","",IFERROR(IF(VLOOKUP($M17,'Casos y evidencias'!$A$6:$O$83,11,FALSE)="","",VLOOKUP($M17,'Casos y evidencias'!$A$6:$O$83,11,FALSE)),"ID no encontrado")) | Q17: =IF($M17="","",IFERROR(IF(VLOOKUP($M17,'Casos y evidencias'!$A$6:$O$83,12,FALSE)="","",VLOOKUP($M17,'Casos y evidencias'!$A$6:$O$83,12,FALSE)),"ID no encontrado"))
A18: 11 | B18: =IF($G18="","",IF($K18="","Falta criterio",IFERROR(IF(VLOOKUP($K18,'Historias y criterios'!$A$6:$P$83,3,FALSE)<>$G18,"Revisar relación requisito-criterio",IF($M18="","Falta caso de prueba",IF(VLOOKUP($M18,'Casos y evidencias'!$A$6:$O$83,2,FALSE)<>$K18,"Revisar relación criterio-caso",IF($O18="Aprobado",IF($P18="","Falta evidencia","Trazabilidad completa"),IF($O18="Fallido","Prueba fallida",IF($O18="Bloqueado","Prueba bloqueada","Prueba pendiente")))))),"ID no encontrado"))) -> Prueba pendiente | C18: =IF($G18="","",IFERROR(IF(VLOOKUP($G18,Requerimientos!$A$6:$M$43,2,FALSE)="","",VLOOKUP($G18,Requerimientos!$A$6:$M$43,2,FALSE)),"ID no encontrado")) -> OBJ-001 | D18: =IF($C18="","",IFERROR(IF(VLOOKUP($C18,'Objetivos y procesos'!$A$6:$H$35,2,FALSE)="","",VLOOKUP($C18,'Objetivos y procesos'!$A$6:$H$35,2,FALSE)),"ID no encontrado")) -> Proteger la plataforma y asegurar que cada usuario opere con el perfil, empresa y vendedor correctos. | E18: =IF($G18="","",IFERROR(IF(VLOOKUP($G18,Requerimientos!$A$6:$M$43,3,FALSE)="","",VLOOKUP($G18,Requerimientos!$A$6:$M$43,3,FALSE)),"ID no encontrado")) -> PR-01 | F18: =IF($E18="","",IFERROR(IF(INDEX('Objetivos y procesos'!$D$6:$D$35,MATCH($E18,'Objetivos y procesos'!$C$6:$C$35,0))="","",IF(INDEX('Objetivos y procesos'!$D$6:$D$35,MATCH($E18,'Objetivos y procesos'!$C$6:$C$35,0))=INDEX('Objetivos y procesos'!$E$6:$E$35,MATCH($E18,'Objetivos y procesos'!$C$6:$C$35,0)),INDEX('Objetivos y procesos'!$D$6:$D$35,MATCH($E18,'Objetivos y procesos'!$C$6:$C$35,0)),INDEX('Objetivos y procesos'!$D$6:$D$35,MATCH($E18,'Objetivos y procesos'!$C$6:$C$35,0))&IF(INDEX('Objetivos y procesos'!$E$6:$E$35,MATCH($E18,'Objetivos y procesos'!$C$6:$C$35,0))="",""," / "&INDEX('Objetivos y procesos'!$E$6:$E$35,MATCH($E18,'Objetivos y procesos'!$C$6:$C$35,0))))),"ID no encontrado")) -> Gestión de usuarios, roles y permisos | G18: RF-35 | H18: =IF($G18="","",IFERROR(IF(VLOOKUP($G18,Requerimientos!$A$6:$M$43,7,FALSE)="","",VLOOKUP($G18,Requerimientos!$A$6:$M$43,7,FALSE)),"ID no encontrado")) -> El sistema debe permitir asociar a cada usuario, sea vendedor o asistente de vendedor, uno o más códigos de vendedor de SAP (SlpCode), cada uno vinculado a su empresa: Ferretería Marsella o Asland. | I18: =IF($K18="","",IFERROR(IF(VLOOKUP($K18,'Historias y criterios'!$A$6:$P$83,2,FALSE)="","",VLOOKUP($K18,'Historias y criterios'!$A$6:$P$83,2,FALSE)),"ID no encontrado")) -> HU-004 | J18: =IF($K18="","",IFERROR(IF(VLOOKUP($K18,'Historias y criterios'!$A$6:$P$83,10,FALSE)="","",VLOOKUP($K18,'Historias y criterios'!$A$6:$P$83,10,FALSE)),"ID no encontrado")) -> Como administrador, quiero asociar SlpCode y escala de comisión por empresa a vendedores y asistentes, para asegurar que cada operación use la empresa y el vendedor correctos | K18: CA-011 | L18: =IF($K18="","",IFERROR(IF(VLOOKUP($K18,'Historias y criterios'!$A$6:$P$83,11,FALSE)="","",VLOOKUP($K18,'Historias y criterios'!$A$6:$P$83,11,FALSE)),"ID no encontrado")) -> Cada SlpCode queda asociado a Marsella o Asland y a los usuarios autorizados. | M18: CP-011 | N18: =IF($M18="","",IFERROR(IF(VLOOKUP($M18,'Casos y evidencias'!$A$6:$O$83,5,FALSE)="","",VLOOKUP($M18,'Casos y evidencias'!$A$6:$O$83,5,FALSE)),"ID no encontrado")) -> Asociación de SlpCode por empresa | O18: =IF($M18="","",IFERROR(IF(VLOOKUP($M18,'Casos y evidencias'!$A$6:$O$83,10,FALSE)="","",VLOOKUP($M18,'Casos y evidencias'!$A$6:$O$83,10,FALSE)),"ID no encontrado")) -> No ejecutado | P18: =IF($M18="","",IFERROR(IF(VLOOKUP($M18,'Casos y evidencias'!$A$6:$O$83,11,FALSE)="","",VLOOKUP($M18,'Casos y evidencias'!$A$6:$O$83,11,FALSE)),"ID no encontrado")) | Q18: =IF($M18="","",IFERROR(IF(VLOOKUP($M18,'Casos y evidencias'!$A$6:$O$83,12,FALSE)="","",VLOOKUP($M18,'Casos y evidencias'!$A$6:$O$83,12,FALSE)),"ID no encontrado"))
A19: 12 | B19: =IF($G19="","",IF($K19="","Falta criterio",IFERROR(IF(VLOOKUP($K19,'Historias y criterios'!$A$6:$P$83,3,FALSE)<>$G19,"Revisar relación requisito-criterio",IF($M19="","Falta caso de prueba",IF(VLOOKUP($M19,'Casos y evidencias'!$A$6:$O$83,2,FALSE)<>$K19,"Revisar relación criterio-caso",IF($O19="Aprobado",IF($P19="","Falta evidencia","Trazabilidad completa"),IF($O19="Fallido","Prueba fallida",IF($O19="Bloqueado","Prueba bloqueada","Prueba pendiente")))))),"ID no encontrado"))) -> Prueba pendiente | C19: =IF($G19="","",IFERROR(IF(VLOOKUP($G19,Requerimientos!$A$6:$M$43,2,FALSE)="","",VLOOKUP($G19,Requerimientos!$A$6:$M$43,2,FALSE)),"ID no encontrado")) -> OBJ-003 | D19: =IF($C19="","",IFERROR(IF(VLOOKUP($C19,'Objetivos y procesos'!$A$6:$H$35,2,FALSE)="","",VLOOKUP($C19,'Objetivos y procesos'!$A$6:$H$35,2,FALSE)),"ID no encontrado")) -> Centralizar consultas, cotizaciones y órdenes de venta, aplicando vendedor, comisión, autorización e integración correctos. | E19: =IF($G19="","",IFERROR(IF(VLOOKUP($G19,Requerimientos!$A$6:$M$43,3,FALSE)="","",VLOOKUP($G19,Requerimientos!$A$6:$M$43,3,FALSE)),"ID no encontrado")) -> PR-03 | F19: =IF($E19="","",IFERROR(IF(INDEX('Objetivos y procesos'!$D$6:$D$35,MATCH($E19,'Objetivos y procesos'!$C$6:$C$35,0))="","",IF(INDEX('Objetivos y procesos'!$D$6:$D$35,MATCH($E19,'Objetivos y procesos'!$C$6:$C$35,0))=INDEX('Objetivos y procesos'!$E$6:$E$35,MATCH($E19,'Objetivos y procesos'!$C$6:$C$35,0)),INDEX('Objetivos y procesos'!$D$6:$D$35,MATCH($E19,'Objetivos y procesos'!$C$6:$C$35,0)),INDEX('Objetivos y procesos'!$D$6:$D$35,MATCH($E19,'Objetivos y procesos'!$C$6:$C$35,0))&IF(INDEX('Objetivos y procesos'!$E$6:$E$35,MATCH($E19,'Objetivos y procesos'!$C$6:$C$35,0))="",""," / "&INDEX('Objetivos y procesos'!$E$6:$E$35,MATCH($E19,'Objetivos y procesos'!$C$6:$C$35,0))))),"ID no encontrado")) -> Gestión comercial, cotizaciones y órdenes de venta | G19: RF-36 | H19: =IF($G19="","",IFERROR(IF(VLOOKUP($G19,Requerimientos!$A$6:$M$43,7,FALSE)="","",VLOOKUP($G19,Requerimientos!$A$6:$M$43,7,FALSE)),"ID no encontrado")) -> El sistema debe permitir al administrador asignar a cada código de vendedor, al editar su perfil, la escala de comisión con que se calcula su comisión. | I19: =IF($K19="","",IFERROR(IF(VLOOKUP($K19,'Historias y criterios'!$A$6:$P$83,2,FALSE)="","",VLOOKUP($K19,'Historias y criterios'!$A$6:$P$83,2,FALSE)),"ID no encontrado")) -> HU-004 | J19: =IF($K19="","",IFERROR(IF(VLOOKUP($K19,'Historias y criterios'!$A$6:$P$83,10,FALSE)="","",VLOOKUP($K19,'Historias y criterios'!$A$6:$P$83,10,FALSE)),"ID no encontrado")) -> Como administrador, quiero asociar SlpCode y escala de comisión por empresa a vendedores y asistentes, para asegurar que cada operación use la empresa y el vendedor correctos | K19: CA-012 | L19: =IF($K19="","",IFERROR(IF(VLOOKUP($K19,'Historias y criterios'!$A$6:$P$83,11,FALSE)="","",VLOOKUP($K19,'Historias y criterios'!$A$6:$P$83,11,FALSE)),"ID no encontrado")) -> Se asigna una escala de comisión o se usa la escala predeterminada. | M19: CP-012 | N19: =IF($M19="","",IFERROR(IF(VLOOKUP($M19,'Casos y evidencias'!$A$6:$O$83,5,FALSE)="","",VLOOKUP($M19,'Casos y evidencias'!$A$6:$O$83,5,FALSE)),"ID no encontrado")) -> Asignación de escala de comisión | O19: =IF($M19="","",IFERROR(IF(VLOOKUP($M19,'Casos y evidencias'!$A$6:$O$83,10,FALSE)="","",VLOOKUP($M19,'Casos y evidencias'!$A$6:$O$83,10,FALSE)),"ID no encontrado")) -> No ejecutado | P19: =IF($M19="","",IFERROR(IF(VLOOKUP($M19,'Casos y evidencias'!$A$6:$O$83,11,FALSE)="","",VLOOKUP($M19,'Casos y evidencias'!$A$6:$O$83,11,FALSE)),"ID no encontrado")) | Q19: =IF($M19="","",IFERROR(IF(VLOOKUP($M19,'Casos y evidencias'!$A$6:$O$83,12,FALSE)="","",VLOOKUP($M19,'Casos y evidencias'!$A$6:$O$83,12,FALSE)),"ID no encontrado"))
... A85: 78 | B85: =IF($G85="","",IF($K85="","Falta criterio",IFERROR(IF(VLOOKUP($K85,'Historias y criterios'!$A$6:$P$83,3,FALSE)<>$G85,"Revisar relación requisito-criterio",IF($M85="","Falta caso de prueba",IF(VLOOKUP($M85,'Casos y evidencias'!$A$6:$O$83,2,FALSE)<>$K85,"Revisar relación criterio-caso",IF($O85="Aprobado",IF($P85="","Falta evidencia","Trazabilidad completa"),IF($O85="Fallido","Prueba fallida",IF($O85="Bloqueado","Prueba bloqueada","Prueba pendiente")))))),"ID no encontrado"))) -> Prueba pendiente | C85: =IF($G85="","",IFERROR(IF(VLOOKUP($G85,Requerimientos!$A$6:$M$43,2,FALSE)="","",VLOOKUP($G85,Requerimientos!$A$6:$M$43,2,FALSE)),"ID no encontrado")) -> OBJ-006 | D85: =IF($C85="","",IFERROR(IF(VLOOKUP($C85,'Objetivos y procesos'!$A$6:$H$35,2,FALSE)="","",VLOOKUP($C85,'Objetivos y procesos'!$A$6:$H$35,2,FALSE)),"ID no encontrado")) -> Centralizar la posventa y ofrecer visibilidad de cada caso, comprobante y decisión a los participantes autorizados. | E85: =IF($G85="","",IFERROR(IF(VLOOKUP($G85,Requerimientos!$A$6:$M$43,3,FALSE)="","",VLOOKUP($G85,Requerimientos!$A$6:$M$43,3,FALSE)),"ID no encontrado")) -> PR-06 | F85: =IF($E85="","",IFERROR(IF(INDEX('Objetivos y procesos'!$D$6:$D$35,MATCH($E85,'Objetivos y procesos'!$C$6:$C$35,0))="","",IF(INDEX('Objetivos y procesos'!$D$6:$D$35,MATCH($E85,'Objetivos y procesos'!$C$6:$C$35,0))=INDEX('Objetivos y procesos'!$E$6:$E$35,MATCH($E85,'Objetivos y procesos'!$C$6:$C$35,0)),INDEX('Objetivos y procesos'!$D$6:$D$35,MATCH($E85,'Objetivos y procesos'!$C$6:$C$35,0)),INDEX('Objetivos y procesos'!$D$6:$D$35,MATCH($E85,'Objetivos y procesos'!$C$6:$C$35,0))&IF(INDEX('Objetivos y procesos'!$E$6:$E$35,MATCH($E85,'Objetivos y procesos'!$C$6:$C$35,0))="",""," / "&INDEX('Objetivos y procesos'!$E$6:$E$35,MATCH($E85,'Objetivos y procesos'!$C$6:$C$35,0))))),"ID no encontrado")) -> Gestión de Posventa | G85: RF-34 | H85: =IF($G85="","",IFERROR(IF(VLOOKUP($G85,Requerimientos!$A$6:$M$43,7,FALSE)="","",VLOOKUP($G85,Requerimientos!$A$6:$M$43,7,FALSE)),"ID no encontrado")) -> El sistema debe permitir al autorizador de posventa cerrar un caso, registrando su resolución final. | I85: =IF($K85="","",IFERROR(IF(VLOOKUP($K85,'Historias y criterios'!$A$6:$P$83,2,FALSE)="","",VLOOKUP($K85,'Historias y criterios'!$A$6:$P$83,2,FALSE)),"ID no encontrado")) -> HU-020 | J85: =IF($K85="","",IFERROR(IF(VLOOKUP($K85,'Historias y criterios'!$A$6:$P$83,10,FALSE)="","",VLOOKUP($K85,'Historias y criterios'!$A$6:$P$83,10,FALSE)),"ID no encontrado")) -> Como autorizador de posventa, quiero actualizar el caso por sus estados y registrar su resolución final, para mantener el seguimiento hasta un cierre controlado | K85: CA-078 | L85: =IF($K85="","",IFERROR(IF(VLOOKUP($K85,'Historias y criterios'!$A$6:$P$83,11,FALSE)="","",VLOOKUP($K85,'Historias y criterios'!$A$6:$P$83,11,FALSE)),"ID no encontrado")) -> Solo el autorizador cierra el caso; un caso cerrado no acepta nuevos cambios. | M85: CP-078 | N85: =IF($M85="","",IFERROR(IF(VLOOKUP($M85,'Casos y evidencias'!$A$6:$O$83,5,FALSE)="","",VLOOKUP($M85,'Casos y evidencias'!$A$6:$O$83,5,FALSE)),"ID no encontrado")) -> Cierre exclusivo y bloqueo posterior | O85: =IF($M85="","",IFERROR(IF(VLOOKUP($M85,'Casos y evidencias'!$A$6:$O$83,10,FALSE)="","",VLOOKUP($M85,'Casos y evidencias'!$A$6:$O$83,10,FALSE)),"ID no encontrado")) -> No ejecutado | P85: =IF($M85="","",IFERROR(IF(VLOOKUP($M85,'Casos y evidencias'!$A$6:$O$83,11,FALSE)="","",VLOOKUP($M85,'Casos y evidencias'!$A$6:$O$83,11,FALSE)),"ID no encontrado")) | Q85: =IF($M85="","",IFERROR(IF(VLOOKUP($M85,'Casos y evidencias'!$A$6:$O$83,12,FALSE)="","",VLOOKUP($M85,'Casos y evidencias'!$A$6:$O$83,12,FALSE)),"ID no encontrado"))

Sheet Objetivos y procesos
A2: Objetivos y procesos
A4: Relacione cada objetivo del proyecto con un proceso AS-IS o TO-BE. Puede repetir un proceso en varias filas si lo necesita.
A5: ID Objetivo | B5: Objetivo | C5: ID Proceso | D5: Proceso | E5: Módulo | F5: Indicador / Resultado esperado | G5: Responsable | H5: Estado
A6: OBJ-001 | B6: Proteger la plataforma y asegurar que cada usuario opere con el perfil, empresa y vendedor correctos. | C6: PR-01 | D6: Gestión de usuarios, roles y permisos | E6: Gestión de usuarios, roles y permisos | F6: HU-001 a HU-004 aceptadas; permisos validados en servidor y trazabilidad de accesos comprobada. | G6: Matías y Alexssander | H6: En revisión
A7: OBJ-002 | B7: Reducir reprocesos y hacer visible la creación, activación o modificación de artículos desde su envío hasta la resolución. | C7: PR-02 | D7: Solicitudes y autorizaciones | E7: Solicitudes y autorizaciones | F7: HU-005 a HU-007 aceptadas; estados, reglas de adjuntos, permisos y resolución trazable verificados. | G7: Millaray y Matías | H7: En revisión
A8: OBJ-003 | B8: Centralizar consultas, cotizaciones y órdenes de venta, aplicando vendedor, comisión, autorización e integración correctos. | C8: PR-03 | D8: Gestión comercial, cotizaciones y órdenes de venta | E8: Gestión comercial, cotizaciones y órdenes de venta | F8: HU-008 a HU-011 aceptadas; documentos y restricciones comerciales probados de extremo a extremo. | G8: Alexssander y Millaray | H8: En revisión
A9: OBJ-004 | B9: Entregar avisos oportunos y una trazabilidad común para todos los procesos incorporados. | C9: PR-04 | D9: Notificaciones y trazabilidad | E9: Notificaciones y trazabilidad | F9: HU-012 a HU-014 aceptadas; privacidad, recordatorios e historial verificados en los procesos integrados. | G9: Millaray y Matías | H9: En revisión
A10: OBJ-005 | B10: Canalizar lecturas por API sobre HANA y escrituras autorizadas por Service Layer sin duplicidad ni operaciones parciales. | C10: PR-05 | D10: Integración con SAP Business One | E10: Integración con SAP Business One | F10: HU-015 a HU-017 aceptadas; seguridad, rendimiento, integridad e idempotencia comprobados. | G10: Alexssander y Matías | H10: En revisión
A11: OBJ-006 | B11: Centralizar la posventa y ofrecer visibilidad de cada caso, comprobante y decisión a los participantes autorizados. | C11: PR-06 | D11: Gestión de Posventa | E11: Gestión de Posventa | F11: HU-018 a HU-020 aceptadas; rutas por guía o factura, QR, permisos, notificaciones y cierre verificados. | G11: Millaray y Alexssander | H11: En revisión
A12: OBJ-007 | H12: Borrador
A13: OBJ-008 | H13: Borrador
A14: OBJ-009 | H14: Borrador
A15: OBJ-010 | H15: Borrador
A16: OBJ-011 | H16: Borrador
A17: OBJ-012 | H17: Borrador
A18: OBJ-013 | H18: Borrador
A19: OBJ-014 | H19: Borrador
A20: OBJ-015 | H20: Borrador
A21: OBJ-016 | H21: Borrador
A22: OBJ-017 | H22: Borrador
A23: OBJ-018 | H23: Borrador
... A35: OBJ-030 | H35: Borrador

Sheet Requerimientos
A2: Requerimientos
A4: Registre cada requerimiento y vincúlelo con su objetivo y proceso mediante los códigos correspondientes.
A5: ID Requerimiento | B5: ID Objetivo | C5: ID Proceso | D5: Tipo | E5: Módulo | F5: Nombre corto | G5: Descripción | H5: Fuente | I5: Prioridad | J5: Dependencias | K5: Estado | L5: Responsable | M5: Versión
A6: RF-01 | B6: OBJ-001 | C6: PR-01 | D6: Funcional | E6: =IF(C6="","",IFERROR(IF(INDEX('Objetivos y procesos'!$E$6:$E$35,MATCH(C6,'Objetivos y procesos'!$C$6:$C$35,0))="","",INDEX('Objetivos y procesos'!$E$6:$E$35,MATCH(C6,'Objetivos y procesos'!$C$6:$C$35,0))),"ID no encontrado")) -> Gestión de usuarios, roles y permisos | F6: Autenticación de usuarios | G6: El sistema debe permitir que un usuario se autentique mediante usuario y contraseña. | H6: ERS v2.0 (Doc. 9) · Carta 7.1 | I6: Alta | J6: RN-02 · RNF-01, RNF-04, RNF-05 | K6: En análisis | L6: Matías y Alexssander | M6: 2.0
A7: RF-02 | B7: OBJ-001 | C7: PR-01 | D7: Funcional | E7: =IF(C7="","",IFERROR(IF(INDEX('Objetivos y procesos'!$E$6:$E$35,MATCH(C7,'Objetivos y procesos'!$C$6:$C$35,0))="","",INDEX('Objetivos y procesos'!$E$6:$E$35,MATCH(C7,'Objetivos y procesos'!$C$6:$C$35,0))),"ID no encontrado")) -> Gestión de usuarios, roles y permisos | F7: Asignación de área, cargo y rol | G7: El sistema debe permitir asignar a cada usuario un área, un cargo y un rol. | H7: ERS v2.0 (Doc. 9) · Carta 7.1 | I7: Alta | J7: RN-01 | K7: En análisis | L7: Matías y Alexssander | M7: 2.0
A8: RF-03 | B8: OBJ-001 | C8: PR-01 | D8: Funcional | E8: =IF(C8="","",IFERROR(IF(INDEX('Objetivos y procesos'!$E$6:$E$35,MATCH(C8,'Objetivos y procesos'!$C$6:$C$35,0))="","",INDEX('Objetivos y procesos'!$E$6:$E$35,MATCH(C8,'Objetivos y procesos'!$C$6:$C$35,0))),"ID no encontrado")) -> Gestión de usuarios, roles y permisos | F8: Restricción por rol, área y cargo | G8: El sistema debe restringir las funciones y los datos visibles según el rol, el área y el cargo del usuario. | H8: ERS v2.0 (Doc. 9) · Carta 7.1 | I8: Alta | J8: RN-03 · RNF-02 | K8: En análisis | L8: Matías y Alexssander | M8: 2.0
A9: RF-04 | B9: OBJ-001 | C9: PR-01 | D9: Funcional | E9: =IF(C9="","",IFERROR(IF(INDEX('Objetivos y procesos'!$E$6:$E$35,MATCH(C9,'Objetivos y procesos'!$C$6:$C$35,0))="","",INDEX('Objetivos y procesos'!$E$6:$E$35,MATCH(C9,'Objetivos y procesos'!$C$6:$C$35,0))),"ID no encontrado")) -> Gestión de usuarios, roles y permisos | F9: Administración de usuarios | G9: El sistema debe permitir al administrador crear, editar, desactivar y reactivar usuarios. | H9: ERS v2.0 (Doc. 9) · Carta 7.1 | I9: Alta | J9: RN-02, RN-04 | K9: En análisis | L9: Matías y Alexssander | M9: 2.0
A10: RF-05 | B10: OBJ-001 | C10: PR-01 | D10: Funcional | E10: =IF(C10="","",IFERROR(IF(INDEX('Objetivos y procesos'!$E$6:$E$35,MATCH(C10,'Objetivos y procesos'!$C$6:$C$35,0))="","",INDEX('Objetivos y procesos'!$E$6:$E$35,MATCH(C10,'Objetivos y procesos'!$C$6:$C$35,0))),"ID no encontrado")) -> Gestión de usuarios, roles y permisos | F10: Definición de permisos | G10: El sistema debe permitir al administrador definir y modificar los permisos asociados a cada rol, área y cargo. | H10: ERS v2.0 (Doc. 9) · Carta 7.1 | I10: Media | J10: RN-03, RN-04 · RNF-02 | K10: En análisis | L10: Matías y Alexssander | M10: 2.0
A11: RF-06 | B11: OBJ-002 | C11: PR-02 | D11: Funcional | E11: =IF(C11="","",IFERROR(IF(INDEX('Objetivos y procesos'!$E$6:$E$35,MATCH(C11,'Objetivos y procesos'!$C$6:$C$35,0))="","",INDEX('Objetivos y procesos'!$E$6:$E$35,MATCH(C11,'Objetivos y procesos'!$C$6:$C$35,0))),"ID no encontrado")) -> Solicitudes y autorizaciones | F11: Creación y envío de solicitud de código | G11: El sistema debe permitir al usuario con permiso de enviar solicitudes de código crear una solicitud de creación, activación o modificación de códigos de producto y enviarla a revisión del grupo autorizador correspondiente. | H11: ERS v2.0 (Doc. 9) · Carta 7.2 | I11: Alta | J11: RN-06, RN-07, RN-11 | K11: En análisis | L11: Millaray y Matías | M11: 2.0
A12: RF-07 | B12: OBJ-002 | C12: PR-02 | D12: Funcional | E12: =IF(C12="","",IFERROR(IF(INDEX('Objetivos y procesos'!$E$6:$E$35,MATCH(C12,'Objetivos y procesos'!$C$6:$C$35,0))="","",INDEX('Objetivos y procesos'!$E$6:$E$35,MATCH(C12,'Objetivos y procesos'!$C$6:$C$35,0))),"ID no encontrado")) -> Solicitudes y autorizaciones | F12: Aprobación o rechazo de solicitudes | G12: El sistema debe permitir al autorizador aprobar o rechazar una solicitud, registrando el motivo cuando la rechaza. | H12: ERS v2.0 (Doc. 9) · Carta 7.2 | I12: Alta | J12: RN-07, RN-08, RN-10 · RNF-14 | K12: En análisis | L12: Millaray y Matías | M12: 2.0
A13: RF-08 | B13: OBJ-002 | C13: PR-02 | D13: Funcional | E13: =IF(C13="","",IFERROR(IF(INDEX('Objetivos y procesos'!$E$6:$E$35,MATCH(C13,'Objetivos y procesos'!$C$6:$C$35,0))="","",INDEX('Objetivos y procesos'!$E$6:$E$35,MATCH(C13,'Objetivos y procesos'!$C$6:$C$35,0))),"ID no encontrado")) -> Solicitudes y autorizaciones | F13: Corrección y reenvío de solicitudes | G13: El sistema debe permitir al vendedor corregir y reenviar una solicitud rechazada por el autorizador. | H13: ERS v2.0 (Doc. 9) · Carta 7.2 | I13: Alta | J13: RN-08, RN-09 | K13: En análisis | L13: Millaray y Matías | M13: 2.0
A14: RF-09 | B14: OBJ-002 | C14: PR-02 | D14: Funcional | E14: =IF(C14="","",IFERROR(IF(INDEX('Objetivos y procesos'!$E$6:$E$35,MATCH(C14,'Objetivos y procesos'!$C$6:$C$35,0))="","",INDEX('Objetivos y procesos'!$E$6:$E$35,MATCH(C14,'Objetivos y procesos'!$C$6:$C$35,0))),"ID no encontrado")) -> Solicitudes y autorizaciones | F14: Consulta del estado de solicitudes | G14: El sistema debe permitir consultar el estado actual, el responsable, la fecha de respuesta y el comentario de cada solicitud. | H14: ERS v2.0 (Doc. 9) · Carta 7.2 | I14: Alta | J14: RN-09, RN-10 | K14: En análisis | L14: Millaray y Matías | M14: 2.0
A15: RF-10 | B15: OBJ-002 | C15: PR-02 | D15: Funcional | E15: =IF(C15="","",IFERROR(IF(INDEX('Objetivos y procesos'!$E$6:$E$35,MATCH(C15,'Objetivos y procesos'!$C$6:$C$35,0))="","",INDEX('Objetivos y procesos'!$E$6:$E$35,MATCH(C15,'Objetivos y procesos'!$C$6:$C$35,0))),"ID no encontrado")) -> Solicitudes y autorizaciones | F15: Filtro y búsqueda de solicitudes | G15: El sistema debe permitir filtrar y buscar solicitudes por estado, fecha, área y responsable. | H15: ERS v2.0 (Doc. 9) · Carta 7.2 | I15: Media | J15: RNF-02 | K15: En análisis | L15: Millaray y Matías | M15: 2.0
A16: RF-11 | B16: OBJ-003 | C16: PR-03 | D16: Funcional | E16: =IF(C16="","",IFERROR(IF(INDEX('Objetivos y procesos'!$E$6:$E$35,MATCH(C16,'Objetivos y procesos'!$C$6:$C$35,0))="","",INDEX('Objetivos y procesos'!$E$6:$E$35,MATCH(C16,'Objetivos y procesos'!$C$6:$C$35,0))),"ID no encontrado")) -> Gestión comercial, cotizaciones y órdenes de venta | F16: Consulta de productos y stock | G16: El sistema debe permitir consultar el catálogo de productos con su disponibilidad de stock. | H16: ERS v2.0 (Doc. 9) · Carta 7.3 | I16: Alta | J16: RN-16, RN-17 · RNF-07, RNF-13 | K16: En análisis | L16: Alexssander y Millaray | M16: 2.0
A17: RF-12 | B17: OBJ-003 | C17: PR-03 | D17: Funcional | E17: =IF(C17="","",IFERROR(IF(INDEX('Objetivos y procesos'!$E$6:$E$35,MATCH(C17,'Objetivos y procesos'!$C$6:$C$35,0))="","",INDEX('Objetivos y procesos'!$E$6:$E$35,MATCH(C17,'Objetivos y procesos'!$C$6:$C$35,0))),"ID no encontrado")) -> Gestión comercial, cotizaciones y órdenes de venta | F17: Consulta de clientes, crédito y bloqueo | G17: El sistema debe permitir consultar los datos del cliente, incluidos su crédito disponible y su estado de bloqueo. | H17: ERS v2.0 (Doc. 9) · Carta 7.3 | I17: Alta | J17: RN-13, RN-16, RN-17 · RNF-13 | K17: En análisis | L17: Alexssander y Millaray | M17: 2.0
